Workbook

Sheet Space station challenge
C1: Answer
B2: How long to build one astrahus? | C2: Fully serial (one factory doing every job, one after another): 36,863.75 hours (~1,536 days / ~219.4 weeks / ~4.2 years). This is the total processing time across every extraction/manufacturing cycle needed for all 8 Astrahus blueprint components, computed by expanding the full Bill of Materials tree (Reference sheet, 'Bill of materials' columns) and converting each ingredient quantity into production cycles at its tier's fixed time/output ratio. Full derivation: see 'BOM Cycle Calc' and 'Build Time & Factory Plan' sheets.
B3: If we chose to invest in additional factories how many would be required (and at what levels) to reduce the manufacturing time to one week? | C3: 1,486 factories total across 7 tiers (1,479 beyond a 1-per-tier baseline) using a cost-minimising allocation, reducing total build time from 36,863.75 hrs to 164.2 hours (under the 1-week/168-hour target): Mineral 8, Raw material 297, P1 646, P2 352, P3 133, P4 48, Space station structure 2 (assembly bays). Solved via Lagrangian cost optimisation (minimise total factory spend subject to total build time <= 168 hrs) - see 'Build Time & Factory Plan' sheet, section 2, for the full formula-driven derivation.
B4: What would the breakeven point be? | C4: Using the only cost figures present in the source data (Reference sheet 'Structure pricing', T:U): the factory investment required to hit the 1-week target costs 11,623 (price units per the sheet) and a completed Astrahus structure prices at 2,000 per the same table. Treating that 2,000 as net revenue per completed unit (materials cost not separately available - see note below), breakeven is reached after ceiling(11,623 / 2,000) = 6 completed Astrahus structures. IMPORTANT CAVEAT: the workbook's 'Input prices' section (Reference sheet H:I) lists material categories (Minerals, Cerlestes/PI resources) but was never populated with per-unit ISK prices - only a reference link to evemarketer.com was left. A materials-cost-inclusive breakeven cannot be honestly computed without those live market prices; this answer uses only the cost data actually present in the workbook.
B5: Buy or make input materials? | C5: Buy, for the low-tier bulk commodities - Raw material, P1 and P2 items alone account for 92.7% of all processing hours (Raw 17.6%, P1 50.2%, P2 24.9%; see 'Build Time & Factory Plan'). These are exactly the commodities EVE's market is typically deepest and cheapest for, so self-manufacturing them ties up enormous factory-time for low unit value. Make, for P3/P4 and the final Space station structure components (6.9% of total hours combined) - lower volume, higher value-add, and the item this whole exercise is trying to produce. This is a workload-based recommendation, not a $ margin comparison, because per-unit market prices were not populated in the source workbook (see Q4 caveat) - a live evemarketer.com price pull would let this be re-run as a true buy-vs-make margin per material.

Sheet Reference sheet
C1: Extraction and manufacturing times | H1: Input prices | K1: Material reference | N1: Bill of materials (https://eve-industry.org/calc/) | Q1: Astrahus blueprint | R1: https://evemarketer.com/ | T1: Structure pricing
D3: Time (hrs) | E3: Input | F3: Output | H3: Minerals | I3: Cerlestes | K3: Name | L3: Type | N3: Name | O3: Quantity | Q3: Structure Construction Parts | R3: 1 | T3: Factories | U3: Price per structure
C4: Raw material | D4: 24 | F4: 500000 | I4: Price per unit | K4: Biotech research reports | L4: P3 | N4: Structure Construction Parts | O4: 1 | Q4: Structure Hangar Array | R4: 1 | T4: Mineral | U4: 100
C5: P1 | D5: 0.5 | E5: 3000 | F5: 20 | H5: Isogen | K5: Camera Drones | L5: P3 | N5: Tritanium | O5: 450000 | Q5: Structure Storage Bay | R5: 1 | T5: Raw | U5: 5
C6: P2 | D6: 1 | E6: 40 | F6: 5 | H6: Megacyte | K6: Condensates | L6: P3 | N6: Pyerite | O6: 90000 | Q6: Structure Repair Facility | R6: 1 | T6: P1 | U6: 3
C7: P3 | D7: 1 | E7: 10 | F7: 3 | H7: Mexallon | K7: Cryoprotectant Solution | L7: P3 | N7: Mexallon | O7: 31500 | Q7: Structure Docking Bay | R7: 1 | T7: P2 | U7: 5
C8: P4 | D8: 1 | E8: 6 | F8: 1 | H8: Nocxium | K8: Data Chips | L8: P3 | N8: Isogen | O8: 3600 | Q8: Structure Medical Center | R8: 1 | T8: P3 | U8: 8
C9: Space station structure | D9: 13 | F9: 1 | H9: Pyerite | K9: Gel-Matrix Biopaste | L9: P3 | N9: Nocxium | O9: 675 | Q9: Structure Office Center | R9: 1 | T9: P4 | U9: 12
C10: Mineral | D10: 0.05 | F10: 6000 | H10: Tritanium | K10: Guidance Systems | L10: P3 | N10: Zydrine | O10: 315 | Q10: Structure Market Network | R10: 4 | T10: Space station structure | U10: 2000
H11: Zydrine | K11: Hazmat Detection Systems | L11: P3 | N11: Megacyte | O11: 135
I12: https://evemarketer.com/ | K12: Hermetic Membranes | L12: P3 | N12: Integrity Response Drones | O12: 3
H13: Aqueous Liquids | K13: High-Tech Transmitters | L13: P3 | N13: Gel-Matrix Biopaste | O13: 18
H14: Autotrophs | K14: Industrial Explosives | L14: P3 | N14: Biocells | O14: 60
H15: Base Metals | K15: Neocoms | L15: P3 | N15: Biofuels | O15: 480
H16: Carbon Compounds | K16: Nuclear Reactors | L16: P3 | N16: Carbon Compounds | O16: 72000
H17: Complex Organisms | K17: Planetary Vehicles | L17: P3 | N17: Precious Metals | O17: 480
H18: Felsic Magma | K18: Robotics | L18: P3 | N18: Noble Metals | O18: 72000
H19: Heavy Metals | K19: Smartfab Units | L19: P3 | N19: Oxides | O19: 60
H20: Ionic Solutions | K20: Supercomputers | L20: P3 | N20: Oxidizing Compound | O20: 480
H21: Microorganisms | K21: Synthetic Synapses | L21: P3 | N21: Reactive Gas | O21: 72000
H22: Noble Gas | K22: Transcranial Microcontrollers | L22: P3 | N22: Oxygen | O22: 480
H23: Noble Metals | K23: Ukomi Superconductors | L23: P3 | N23: Noble Gas | O23: 72000
H24: Non-CS Crystals | K24: Vaccines | L24: P3 | N24: Superconductors | O24: 60
... H27: Suspended Plasma | K27: Nano-Factory | L27: P4 | N27: Water | O27: 480
K28: Organic Mortar Applicators | L28: P4 | N28: Aqueous Liquids | O28: 72000
K29: Recursive Computing Module | L29: P4 | N29: Hazmat Detection Systems | O29: 18
K30: Self-Harmonizing Power Core | L30: P4 | N30: Transmitter | O30: 60
K31: Sterile Conduits | L31: P4 | N31: Chiral Structures | O31: 480
K32: Wetware Mainframe | L32: P4 | N32: Non-CS Crystals | O32: 72000
K33: Biocells | L33: P2 | N33: Plasmoids | O33: 480
K34: Construction Blocks | L34: P2 | N34: Suspended Plasma | O34: 72000
K35: Consumer Electronics | L35: P2 | N35: Polytextiles | O35: 60
K36: Coolant | L36: P2 | N36: Biofuels | O36: 480
K37: Enriched Uranium | L37: P2 | N37: Carbon Compounds | O37: 72000
K38: Fertilizer | L38: P2 | N38: Industrial Fibers | O38: 480
K39: Genetically Enhanced Livestock | L39: P2 | N39: Autotrophs | O39: 72000
... K86: Structure Construction Parts | L86: Space station structure | N86: Organic Mortar Applicators | O86: 5
N87: Condensates | O87: 30
N88: Coolant | O88: 100
N89: Water | O89: 800
...

Sheet Tier Params
A1: Tier | B1: Time per cycle (hrs) | C1: Output per cycle
A2: Mineral | B2: 0.05 | C2: 6000
A3: Raw material | B3: 24 | C3: 500000
A4: P1 | B4: 0.5 | C4: 20
A5: P2 | B5: 1 | C5: 5
A6: P3 | B6: 1 | C6: 3
A7: P4 | B7: 1 | C7: 1
A8: Space station structure | B8: 13 | C8: 1
A9: Price per factory (from Reference sheet 'Structure pricing')
A10: Tier | B10: Price per structure
A11: Mineral | B11: 100
A12: Raw material | B12: 5
A13: P1 | B13: 3
A14: P2 | B14: 5
A15: P3 | B15: 8
A16: P4 | B16: 12
A17: Space station structure | B17: 2000

Sheet Item Tier Lookup
A1: Item Name | B1: Tier | C1: Source
A2: Aqueous Liquids | B2: Raw material | C2: Reference sheet H13 (Input prices - Cerlestes/raw)
A3: Autotrophs | B3: Raw material | C3: Reference sheet H14 (Input prices - Cerlestes/raw)
A4: Bacteria | B4: P1 | C4: Reference sheet K57:L57 (Material reference)
A5: Base Metals | B5: Raw material | C5: Reference sheet H15 (Input prices - Cerlestes/raw)
A6: Biocells | B6: P2 | C6: Reference sheet K33:L33 (Material reference)
A7: Biofuels | B7: P1 | C7: Reference sheet K58:L58 (Material reference)
A8: Biomass | B8: P1 | C8: Reference sheet K59:L59 (Material reference)
A9: Biotech research reports | B9: P3 | C9: Reference sheet K4:L4 (Material reference)
A10: Broadcast Node | B10: P4 | C10: Reference sheet K25:L25 (Material reference)
A11: Camera Drones | B11: P3 | C11: Reference sheet K5:L5 (Material reference)
A12: Carbon Compounds | B12: Raw material | C12: Reference sheet H16 (Input prices - Cerlestes/raw)
... A99: Zydrine | B99: Mineral | C99: Reference sheet H11 (Input prices - Minerals)

Sheet BOM Cycle Calc
A1: Ref.Row | B1: Astrahus Component | C1: Item Name | D1: Quantity Required | E1: Tier (VLOOKUP) | F1: Time/cycle hrs (VLOOKUP) | G1: Output/cycle (VLOOKUP) | H1: Cycles Needed (CEILING) | I1: Total Hours
A2: 'Reference sheet'!N4 | B2: Structure Construction Parts | C2: Structure Construction Parts | D2: 1 | E2: =VLOOKUP(C2,'Item Tier Lookup'!$A:$B,2,FALSE) | F2: =VLOOKUP(E2,'Tier Params'!$A:$B,2,FALSE) | G2: =VLOOKUP(E2,'Tier Params'!$A:$C,3,FALSE) | H2: =CEILING(D2/G2,1) | I2: =H2*F2
A3: 'Reference sheet'!N5 | B3: Structure Construction Parts | C3: Tritanium | D3: 450000 | E3: =VLOOKUP(C3,'Item Tier Lookup'!$A:$B,2,FALSE) | F3: =VLOOKUP(E3,'Tier Params'!$A:$B,2,FALSE) | G3: =VLOOKUP(E3,'Tier Params'!$A:$C,3,FALSE) | H3: =CEILING(D3/G3,1) | I3: =H3*F3
A4: 'Reference sheet'!N6 | B4: Structure Construction Parts | C4: Pyerite | D4: 90000 | E4: =VLOOKUP(C4,'Item Tier Lookup'!$A:$B,2,FALSE) | F4: =VLOOKUP(E4,'Tier Params'!$A:$B,2,FALSE) | G4: =VLOOKUP(E4,'Tier Params'!$A:$C,3,FALSE) | H4: =CEILING(D4/G4,1) | I4: =H4*F4
A5: 'Reference sheet'!N7 | B5: Structure Construction Parts | C5: Mexallon | D5: 31500 | E5: =VLOOKUP(C5,'Item Tier Lookup'!$A:$B,2,FALSE) | F5: =VLOOKUP(E5,'Tier Params'!$A:$B,2,FALSE) | G5: =VLOOKUP(E5,'Tier Params'!$A:$C,3,FALSE) | H5: =CEILING(D5/G5,1) | I5: =H5*F5
A6: 'Reference sheet'!N8 | B6: Structure Construction Parts | C6: Isogen | D6: 3600 | E6: =VLOOKUP(C6,'Item Tier Lookup'!$A:$B,2,FALSE) | F6: =VLOOKUP(E6,'Tier Params'!$A:$B,2,FALSE) | G6: =VLOOKUP(E6,'Tier Params'!$A:$C,3,FALSE) | H6: =CEILING(D6/G6,1) | I6: =H6*F6
A7: 'Reference sheet'!N9 | B7: Structure Construction Parts | C7: Nocxium | D7: 675 | E7: =VLOOKUP(C7,'Item Tier Lookup'!$A:$B,2,FALSE) | F7: =VLOOKUP(E7,'Tier Params'!$A:$B,2,FALSE) | G7: =VLOOKUP(E7,'Tier Params'!$A:$C,3,FALSE) | H7: =CEILING(D7/G7,1) | I7: =H7*F7
A8: 'Reference sheet'!N10 | B8: Structure Construction Parts | C8: Zydrine | D8: 315 | E8: =VLOOKUP(C8,'Item Tier Lookup'!$A:$B,2,FALSE) | F8: =VLOOKUP(E8,'Tier Params'!$A:$B,2,FALSE) | G8: =VLOOKUP(E8,'Tier Params'!$A:$C,3,FALSE) | H8: =CEILING(D8/G8,1) | I8: =H8*F8
A9: 'Reference sheet'!N11 | B9: Structure Construction Parts | C9: Megacyte | D9: 135 | E9: =VLOOKUP(C9,'Item Tier Lookup'!$A:$B,2,FALSE) | F9: =VLOOKUP(E9,'Tier Params'!$A:$B,2,FALSE) | G9: =VLOOKUP(E9,'Tier Params'!$A:$C,3,FALSE) | H9: =CEILING(D9/G9,1) | I9: =H9*F9
A10: 'Reference sheet'!N12 | B10: Structure Construction Parts | C10: Integrity Response Drones | D10: 3 | E10: =VLOOKUP(C10,'Item Tier Lookup'!$A:$B,2,FALSE) | F10: =VLOOKUP(E10,'Tier Params'!$A:$B,2,FALSE) | G10: =VLOOKUP(E10,'Tier Params'!$A:$C,3,FALSE) | H10: =CEILING(D10/G10,1) | I10: =H10*F10
A11: 'Reference sheet'!N13 | B11: Structure Construction Parts | C11: Gel-Matrix Biopaste | D11: 18 | E11: =VLOOKUP(C11,'Item Tier Lookup'!$A:$B,2,FALSE) | F11: =VLOOKUP(E11,'Tier Params'!$A:$B,2,FALSE) | G11: =VLOOKUP(E11,'Tier Params'!$A:$C,3,FALSE) | H11: =CEILING(D11/G11,1) | I11: =H11*F11
A12: 'Reference sheet'!N14 | B12: Structure Construction Parts | C12: Biocells | D12: 60 | E12: =VLOOKUP(C12,'Item Tier Lookup'!$A:$B,2,FALSE) | F12: =VLOOKUP(E12,'Tier Params'!$A:$B,2,FALSE) | G12: =VLOOKUP(E12,'Tier Params'!$A:$C,3,FALSE) | H12: =CEILING(D12/G12,1) | I12: =H12*F12
A13: 'Reference sheet'!N15 | B13: Structure Construction Parts | C13: Biofuels | D13: 480 | E13: =VLOOKUP(C13,'Item Tier Lookup'!$A:$B,2,FALSE) | F13: =VLOOKUP(E13,'Tier Params'!$A:$B,2,FALSE) | G13: =VLOOKUP(E13,'Tier Params'!$A:$C,3,FALSE) | H13: =CEILING(D13/G13,1) | I13: =H13*F13
... A1734: 'Reference sheet'!N1736 | B1734: Structure Market Network | C1734: Complex Organisms | D1734: 864000 | E1734: =VLOOKUP(C1734,'Item Tier Lookup'!$A:$B,2,FALSE) | F1734: =VLOOKUP(E1734,'Tier Params'!$A:$B,2,FALSE) | G1734: =VLOOKUP(E1734,'Tier Params'!$A:$C,3,FALSE) | H1734: =CEILING(D1734/G1734,1) | I1734: =H1734*F1734

Sheet Build Time & Factory Plan
A1: 1. Total processing hours required per tier (fully serial, single factory doing every job)
A2: Tier | B2: Total Hours (SUMIF) | C2: Total Cycles | D2: Share of Total
A3: Mineral | B3: =SUMIF('Consolidated Item Demand'!$D:$D,A3,'Consolidated Item Demand'!$H:$H) | C3: =SUMIF('Consolidated Item Demand'!$D:$D,A3,'Consolidated Item Demand'!$G:$G) | D3: =B3/$B$10
A4: Raw material | B4: =SUMIF('Consolidated Item Demand'!$D:$D,A4,'Consolidated Item Demand'!$H:$H) | C4: =SUMIF('Consolidated Item Demand'!$D:$D,A4,'Consolidated Item Demand'!$G:$G) | D4: =B4/$B$10
A5: P1 | B5: =SUMIF('Consolidated Item Demand'!$D:$D,A5,'Consolidated Item Demand'!$H:$H) | C5: =SUMIF('Consolidated Item Demand'!$D:$D,A5,'Consolidated Item Demand'!$G:$G) | D5: =B5/$B$10
A6: P2 | B6: =SUMIF('Consolidated Item Demand'!$D:$D,A6,'Consolidated Item Demand'!$H:$H) | C6: =SUMIF('Consolidated Item Demand'!$D:$D,A6,'Consolidated Item Demand'!$G:$G) | D6: =B6/$B$10
A7: P3 | B7: =SUMIF('Consolidated Item Demand'!$D:$D,A7,'Consolidated Item Demand'!$H:$H) | C7: =SUMIF('Consolidated Item Demand'!$D:$D,A7,'Consolidated Item Demand'!$G:$G) | D7: =B7/$B$10
A8: P4 | B8: =SUMIF('Consolidated Item Demand'!$D:$D,A8,'Consolidated Item Demand'!$H:$H) | C8: =SUMIF('Consolidated Item Demand'!$D:$D,A8,'Consolidated Item Demand'!$G:$G) | D8: =B8/$B$10
A9: Space station structure | B9: =SUMIF('Consolidated Item Demand'!$D:$D,A9,'Consolidated Item Demand'!$H:$H)+8*13 | C9: =SUMIF('Consolidated Item Demand'!$D:$D,A9,'Consolidated Item Demand'!$G:$G)+8 | D9: =B9/$B$10
A10: TOTAL (fully serial build time, 1 factory) | B10: =SUM(B3:B9) | C10: =SUM(C3:C9)
A11: In days: | B11: =B10/24
A12: In weeks: | B12: =B10/168
A14: Note: 'Space station structure' hours include the 13-hr final assembly job for each of the 8 blueprint components (8 x 13 = 104 hrs) added to any sub-component 'Space station structure'-tier ingredient rows (none exist in this BOM). 'Astrahus Component' quantities for Structure Market Network (blueprint qty=4) are taken as already reflected in the source Bill of Materials sheet's row quantities (its raw-material figures scale ~12x vs the qty-1 components), so no further multiplication is applied.
A16: 2. Cost-minimising factory allocation to bring total build time to <= 1 week (168 hrs)
A17: Method: Lagrangian optimisation - minimise total factory cost sum(F[t]*Price[t]) subject to sum(Hours[t]/F[t]) <= 168. Optimum: F[t] = sqrt(Hours[t]/Price[t]) * (S/168), where S = sum of sqrt(Hours[t]*Price[t]) across all tiers.
A19: Tier | B19: Hours | C19: Price/factory | D19: sqrt(Hours x Price) | E19: Factories needed F[t]=CEILING(SQRT(Hours/Price)*(S/168),1) | F19: Resulting time (Hours/F) | G19: Cost = F x Price
A20: =A3 | B20: =B3 | C20: =VLOOKUP(A20,'Tier Params'!$A$11:$B$17,2,FALSE) | D20: =SQRT(B20*C20) | E20: =MAX(1,CEILING(SQRT(B20/C20)*($D$27/168),1)) | F20: =B20/E20 | G20: =E20*C20
A21: =A4 | B21: =B4 | C21: =VLOOKUP(A21,'Tier Params'!$A$11:$B$17,2,FALSE) | D21: =SQRT(B21*C21) | E21: =MAX(1,CEILING(SQRT(B21/C21)*($D$27/168),1)) | F21: =B21/E21 | G21: =E21*C21
A22: =A5 | B22: =B5 | C22: =VLOOKUP(A22,'Tier Params'!$A$11:$B$17,2,FALSE) | D22: =SQRT(B22*C22) | E22: =MAX(1,CEILING(SQRT(B22/C22)*($D$27/168),1)) | F22: =B22/E22 | G22: =E22*C22
A23: =A6 | B23: =B6 | C23: =VLOOKUP(A23,'Tier Params'!$A$11:$B$17,2,FALSE) | D23: =SQRT(B23*C23) | E23: =MAX(1,CEILING(SQRT(B23/C23)*($D$27/168),1)) | F23: =B23/E23 | G23: =E23*C23
A24: =A7 | B24: =B7 | C24: =VLOOKUP(A24,'Tier Params'!$A$11:$B$17,2,FALSE) | D24: =SQRT(B24*C24) | E24: =MAX(1,CEILING(SQRT(B24/C24)*($D$27/168),1)) | F24: =B24/E24 | G24: =E24*C24
A25: =A8 | B25: =B8 | C25: =VLOOKUP(A25,'Tier Params'!$A$11:$B$17,2,FALSE) | D25: =SQRT(B25*C25) | E25: =MAX(1,CEILING(SQRT(B25/C25)*($D$27/168),1)) | F25: =B25/E25 | G25: =E25*C25
A26: =A9 | B26: =B9 | C26: =VLOOKUP(A26,'Tier Params'!$A$11:$B$17,2,FALSE) | D26: =SQRT(B26*C26) | E26: =MAX(1,CEILING(SQRT(B26/C26)*($D$27/168),1)) | F26: =B26/E26 | G26: =E26*C26
A27: S = SUM(sqrt(Hours*Price)) | D27: =SUM(D20:D26)
A28: TOTAL | E28: =SUM(E20:E26) | F28: =SUM(F20:F26) | G28: =SUM(G20:G26)
A29: Additional factories beyond 1-per-tier baseline (7): | E29: =E28-7

Sheet Consolidated Item Demand
A1: Each Astrahus component's ingredient tree contains the same item on multiple branches (e.g. Plasmoids feeding two different sub-parts). Production runs batch by item, so quantities must be summed per (Component, Item) pair BEFORE computing manufacturing cycles - not per raw BOM line - otherwise cycle counts are overstated.
A2: Astrahus Component | B2: Item Name | C2: Quantity Required (SUMIFS of raw BOM rows) | D2: Tier (VLOOKUP) | E2: Time/cycle (VLOOKUP) | F2: Output/cycle (VLOOKUP) | G2: Cycles (CEILING) | H2: Total Hours
A3: Structure Construction Parts | B3: Tritanium | C3: =SUMIFS('BOM Cycle Calc'!$D:$D,'BOM Cycle Calc'!$B:$B,A3,'BOM Cycle Calc'!$C:$C,B3) | D3: =VLOOKUP(B3,'Item Tier Lookup'!$A:$B,2,FALSE) | E3: =VLOOKUP(D3,'Tier Params'!$A:$B,2,FALSE) | F3: =VLOOKUP(D3,'Tier Params'!$A:$C,3,FALSE) | G3: =CEILING(C3/F3,1) | H3: =G3*E3
A4: Structure Construction Parts | B4: Pyerite | C4: =SUMIFS('BOM Cycle Calc'!$D:$D,'BOM Cycle Calc'!$B:$B,A4,'BOM Cycle Calc'!$C:$C,B4) | D4: =VLOOKUP(B4,'Item Tier Lookup'!$A:$B,2,FALSE) | E4: =VLOOKUP(D4,'Tier Params'!$A:$B,2,FALSE) | F4: =VLOOKUP(D4,'Tier Params'!$A:$C,3,FALSE) | G4: =CEILING(C4/F4,1) | H4: =G4*E4
A5: Structure Construction Parts | B5: Mexallon | C5: =SUMIFS('BOM Cycle Calc'!$D:$D,'BOM Cycle Calc'!$B:$B,A5,'BOM Cycle Calc'!$C:$C,B5) | D5: =VLOOKUP(B5,'Item Tier Lookup'!$A:$B,2,FALSE) | E5: =VLOOKUP(D5,'Tier Params'!$A:$B,2,FALSE) | F5: =VLOOKUP(D5,'Tier Params'!$A:$C,3,FALSE) | G5: =CEILING(C5/F5,1) | H5: =G5*E5
A6: Structure Construction Parts | B6: Isogen | C6: =SUMIFS('BOM Cycle Calc'!$D:$D,'BOM Cycle Calc'!$B:$B,A6,'BOM Cycle Calc'!$C:$C,B6) | D6: =VLOOKUP(B6,'Item Tier Lookup'!$A:$B,2,FALSE) | E6: =VLOOKUP(D6,'Tier Params'!$A:$B,2,FALSE) | F6: =VLOOKUP(D6,'Tier Params'!$A:$C,3,FALSE) | G6: =CEILING(C6/F6,1) | H6: =G6*E6
A7: Structure Construction Parts | B7: Nocxium | C7: =SUMIFS('BOM Cycle Calc'!$D:$D,'BOM Cycle Calc'!$B:$B,A7,'BOM Cycle Calc'!$C:$C,B7) | D7: =VLOOKUP(B7,'Item Tier Lookup'!$A:$B,2,FALSE) | E7: =VLOOKUP(D7,'Tier Params'!$A:$B,2,FALSE) | F7: =VLOOKUP(D7,'Tier Params'!$A:$C,3,FALSE) | G7: =CEILING(C7/F7,1) | H7: =G7*E7
A8: Structure Construction Parts | B8: Zydrine | C8: =SUMIFS('BOM Cycle Calc'!$D:$D,'BOM Cycle Calc'!$B:$B,A8,'BOM Cycle Calc'!$C:$C,B8) | D8: =VLOOKUP(B8,'Item Tier Lookup'!$A:$B,2,FALSE) | E8: =VLOOKUP(D8,'Tier Params'!$A:$B,2,FALSE) | F8: =VLOOKUP(D8,'Tier Params'!$A:$C,3,FALSE) | G8: =CEILING(C8/F8,1) | H8: =G8*E8
A9: Structure Construction Parts | B9: Megacyte | C9: =SUMIFS('BOM Cycle Calc'!$D:$D,'BOM Cycle Calc'!$B:$B,A9,'BOM Cycle Calc'!$C:$C,B9) | D9: =VLOOKUP(B9,'Item Tier Lookup'!$A:$B,2,FALSE) | E9: =VLOOKUP(D9,'Tier Params'!$A:$B,2,FALSE) | F9: =VLOOKUP(D9,'Tier Params'!$A:$C,3,FALSE) | G9: =CEILING(C9/F9,1) | H9: =G9*E9
A10: Structure Construction Parts | B10: Integrity Response Drones | C10: =SUMIFS('BOM Cycle Calc'!$D:$D,'BOM Cycle Calc'!$B:$B,A10,'BOM Cycle Calc'!$C:$C,B10) | D10: =VLOOKUP(B10,'Item Tier Lookup'!$A:$B,2,FALSE) | E10: =VLOOKUP(D10,'Tier Params'!$A:$B,2,FALSE) | F10: =VLOOKUP(D10,'Tier Params'!$A:$C,3,FALSE) | G10: =CEILING(C10/F10,1) | H10: =G10*E10
A11: Structure Construction Parts | B11: Gel-Matrix Biopaste | C11: =SUMIFS('BOM Cycle Calc'!$D:$D,'BOM Cycle Calc'!$B:$B,A11,'BOM Cycle Calc'!$C:$C,B11) | D11: =VLOOKUP(B11,'Item Tier Lookup'!$A:$B,2,FALSE) | E11: =VLOOKUP(D11,'Tier Params'!$A:$B,2,FALSE) | F11: =VLOOKUP(D11,'Tier Params'!$A:$C,3,FALSE) | G11: =CEILING(C11/F11,1) | H11: =G11*E11
A12: Structure Construction Parts | B12: Biocells | C12: =SUMIFS('BOM Cycle Calc'!$D:$D,'BOM Cycle Calc'!$B:$B,A12,'BOM Cycle Calc'!$C:$C,B12) | D12: =VLOOKUP(B12,'Item Tier Lookup'!$A:$B,2,FALSE) | E12: =VLOOKUP(D12,'Tier Params'!$A:$B,2,FALSE) | F12: =VLOOKUP(D12,'Tier Params'!$A:$C,3,FALSE) | G12: =CEILING(C12/F12,1) | H12: =G12*E12
A13: Structure Construction Parts | B13: Biofuels | C13: =SUMIFS('BOM Cycle Calc'!$D:$D,'BOM Cycle Calc'!$B:$B,A13,'BOM Cycle Calc'!$C:$C,B13) | D13: =VLOOKUP(B13,'Item Tier Lookup'!$A:$B,2,FALSE) | E13: =VLOOKUP(D13,'Tier Params'!$A:$B,2,FALSE) | F13: =VLOOKUP(D13,'Tier Params'!$A:$C,3,FALSE) | G13: =CEILING(C13/F13,1) | H13: =G13*E13
A14: Structure Construction Parts | B14: Carbon Compounds | C14: =SUMIFS('BOM Cycle Calc'!$D:$D,'BOM Cycle Calc'!$B:$B,A14,'BOM Cycle Calc'!$C:$C,B14) | D14: =VLOOKUP(B14,'Item Tier Lookup'!$A:$B,2,FALSE) | E14: =VLOOKUP(D14,'Tier Params'!$A:$B,2,FALSE) | F14: =VLOOKUP(D14,'Tier Params'!$A:$C,3,FALSE) | G14: =CEILING(C14/F14,1) | H14: =G14*E14
... A661: Structure Market Network | B661: Cryoprotectant Solution | C661: =SUMIFS('BOM Cycle Calc'!$D:$D,'BOM Cycle Calc'!$B:$B,A661,'BOM Cycle Calc'!$C:$C,B661) | D661: =VLOOKUP(B661,'Item Tier Lookup'!$A:$B,2,FALSE) | E661: =VLOOKUP(D661,'Tier Params'!$A:$B,2,FALSE) | F661: =VLOOKUP(D661,'Tier Params'!$A:$C,3,FALSE) | G661: =CEILING(C661/F661,1) | H661: =G661*E661
